<?xml version="1.0"?>
<!-- xMateEB4 industrial standard 6-axis manipulator (4 kg payload) -->
<!-- Kinematics from 仓二 EB4-R596-37 *_mech.cfg + isg/EB4-R596/param.json -->
<!-- Attention: simplified link inertias for visualization / MoveIt -->

<robot name="xMateEB4" xmlns:xacro="http://www.ros.org/wiki/xacro">

  <xacro:arg name="robot_ip" default="192.168.21.10"/>
  <xacro:arg name="local_ip" default="192.168.21.131"/>

  <xacro:include filename="$(find rokae_description)/urdf/materials.xacro"/>
  <xacro:property name="nameofManipulator" value="xMateEB4"/>

  <!-- Joint limits: JOINT_RANGE_*_CUSTOMIZE from EB4-R596-37_mech.cfg (deg -> rad) -->
  <xacro:property name="j1_lo" value="-2.9670597283903604"/>
  <xacro:property name="j1_hi" value="2.9670597283903604"/>
  <xacro:property name="j2_lo" value="-1.3962634015954636"/>
  <xacro:property name="j2_hi" value="2.5132741228718345"/>
  <xacro:property name="j3_lo" value="-3.3859385131987587"/>
  <xacro:property name="j3_hi" value="0.9424777960769377"/>
  <xacro:property name="j4_lo" value="-2.9670597283903604"/>
  <xacro:property name="j4_hi" value="2.9670597283903604"/>
  <xacro:property name="j5_lo" value="-2.076941553646873"/>
  <xacro:property name="j5_hi" value="2.076941553646873"/>
  <xacro:property name="j6_lo" value="-6.283185307179586"/>
  <xacro:property name="j6_hi" value="6.283185307179586"/>

  <!-- JOINT_MAX_SPEED from EB4-R596-37_mech.cfg MOTION (deg/s -> rad/s) -->
  <xacro:property name="j1_vel" value="6.457718232379019"/>
  <xacro:property name="j2_vel" value="5.183627878423159"/>
  <xacro:property name="j3_vel" value="6.457718232379019"/>
  <xacro:property name="j4_vel" value="9.337511498169663"/>
  <xacro:property name="j5_vel" value="8.499753457212384"/>
  <xacro:property name="j6_vel" value="13.613568165555769"/>

  <link name="world"/>
  <joint name="fixed" type="fixed">
    <parent link="world"/>
    <child link="${nameofManipulator}_base"/>
  </joint>

  <link name="${nameofManipulator}_base">
    <visual>
      <geometry>
        <mesh filename="package://rokae_description/meshes/${nameofManipulator}/visual/${nameofManipulator}_base.stl" scale="0.001 0.001 0.001"/>
      </geometry>
      <origin rpy="0 0 0" xyz="0 0 0"/>
      <material name="grey"/>
    </visual>
    <inertial>
      <mass value="6.607"/>
      <inertia ixx="0.05" ixy="0" ixz="0" iyy="0.05" iyz="0" izz="0.05"/>
      <origin rpy="0 0 0" xyz="0 0 0.17"/>
    </inertial>
    <collision>
      <geometry>
        <mesh filename="package://rokae_description/meshes/${nameofManipulator}/collision/${nameofManipulator}_base.stl" scale="0.001 0.001 0.001"/>
      </geometry>
      <origin rpy="0 0 0" xyz="0 0 0"/>
    </collision>
  </link>

  <!-- param.json: joint1 at base origin, axis Z -->
  <joint name="joint1" type="revolute">
    <parent link="${nameofManipulator}_base"/>
    <child link="${nameofManipulator}_link1"/>
    <limit effort="4.46" lower="${j1_lo}" upper="${j1_hi}" velocity="${j1_vel}"/>
    <axis xyz="0 0 1"/>
    <origin rpy="0 0 0" xyz="0 0 0"/>
  </joint>

  <link name="${nameofManipulator}_link1">
    <visual>
      <geometry>
        <mesh filename="package://rokae_description/meshes/${nameofManipulator}/visual/${nameofManipulator}_link1.stl" scale="0.001 0.001 0.001"/>
      </geometry>
      <origin rpy="0 0 0" xyz="0 0 0"/>
      <material name="white"/>
    </visual>
    <inertial>
      <mass value="6.607"/>
      <inertia ixx="0.05" ixy="0" ixz="0" iyy="0.05" iyz="0" izz="0.05"/>
      <origin rpy="0 0 0" xyz="0.013 0.019 0.263"/>
    </inertial>
    <collision>
      <geometry>
        <mesh filename="package://rokae_description/meshes/${nameofManipulator}/collision/${nameofManipulator}_link1.stl" scale="0.001 0.001 0.001"/>
      </geometry>
      <origin rpy="0 0 0" xyz="0 0 0"/>
    </collision>
  </link>

  <!-- param.json: joint2 [40, 0, 342] mm, axis Y -->
  <joint name="joint2" type="revolute">
    <parent link="${nameofManipulator}_link1"/>
    <child link="${nameofManipulator}_link2"/>
    <limit effort="4.46" lower="${j2_lo}" upper="${j2_hi}" velocity="${j2_vel}"/>
    <axis xyz="0 1 0"/>
    <origin rpy="0 0 0" xyz="0.04 0 0.342"/>
  </joint>

  <link name="${nameofManipulator}_link2">
    <visual>
      <geometry>
        <mesh filename="package://rokae_description/meshes/${nameofManipulator}/visual/${nameofManipulator}_link2.stl" scale="0.001 0.001 0.001"/>
      </geometry>
      <origin rpy="0 0 0" xyz="0 0 0"/>
      <material name="white"/>
    </visual>
    <inertial>
      <mass value="6.386"/>
      <inertia ixx="0.05" ixy="0" ixz="0" iyy="0.05" iyz="0" izz="0.05"/>
      <origin rpy="0 0 0" xyz="-0.008 0.019 0.123"/>
    </inertial>
    <collision>
      <geometry>
        <mesh filename="package://rokae_description/meshes/${nameofManipulator}/collision/${nameofManipulator}_link2.stl" scale="0.001 0.001 0.001"/>
      </geometry>
      <origin rpy="0 0 0" xyz="0 0 0"/>
    </collision>
  </link>

  <!-- param.json: joint3 [0, 0, 275] mm, axis Y -->
  <joint name="joint3" type="revolute">
    <parent link="${nameofManipulator}_link2"/>
    <child link="${nameofManipulator}_link3"/>
    <limit effort="2.23" lower="${j3_lo}" upper="${j3_hi}" velocity="${j3_vel}"/>
    <axis xyz="0 1 0"/>
    <origin rpy="0 0 0" xyz="0 0 0.275"/>
  </joint>

  <link name="${nameofManipulator}_link3">
    <visual>
      <geometry>
        <mesh filename="package://rokae_description/meshes/${nameofManipulator}/visual/${nameofManipulator}_link3.stl" scale="0.001 0.001 0.001"/>
      </geometry>
      <origin rpy="0 0 0" xyz="0 0 0"/>
      <material name="white"/>
    </visual>
    <inertial>
      <mass value="3.805"/>
      <inertia ixx="0.03" ixy="0" ixz="0" iyy="0.03" iyz="0" izz="0.03"/>
      <origin rpy="0 0 0" xyz="0.022 -0.001 0.009"/>
    </inertial>
    <collision>
      <geometry>
        <mesh filename="package://rokae_description/meshes/${nameofManipulator}/collision/${nameofManipulator}_link3.stl" scale="0.001 0.001 0.001"/>
      </geometry>
      <origin rpy="0 0 0" xyz="0 0 0"/>
    </collision>
  </link>

  <!-- param.json: joint4 [280, 0, 25] mm, axis X -->
  <joint name="joint4" type="revolute">
    <parent link="${nameofManipulator}_link3"/>
    <child link="${nameofManipulator}_link4"/>
    <limit effort="1.11" lower="${j4_lo}" upper="${j4_hi}" velocity="${j4_vel}"/>
    <axis xyz="1 0 0"/>
    <origin rpy="0 0 0" xyz="0.28 0 0.025"/>
  </joint>

  <link name="${nameofManipulator}_link4">
    <visual>
      <geometry>
        <mesh filename="package://rokae_description/meshes/${nameofManipulator}/visual/${nameofManipulator}_link4.stl" scale="0.001 0.001 0.001"/>
      </geometry>
      <origin rpy="0 0 0" xyz="0 0 0"/>
      <material name="white"/>
    </visual>
    <inertial>
      <mass value="2.949"/>
      <inertia ixx="0.02" ixy="0" ixz="0" iyy="0.02" iyz="0" izz="0.02"/>
      <origin rpy="0 0 0" xyz="-0.109 -0.001 0"/>
    </inertial>
    <collision>
      <geometry>
        <mesh filename="package://rokae_description/meshes/${nameofManipulator}/collision/${nameofManipulator}_link4.stl" scale="0.001 0.001 0.001"/>
      </geometry>
      <origin rpy="0 0 0" xyz="0 0 0"/>
    </collision>
  </link>

  <!-- param.json: joint5 at origin, axis Y -->
  <joint name="joint5" type="revolute">
    <parent link="${nameofManipulator}_link4"/>
    <child link="${nameofManipulator}_link5"/>
    <limit effort="0.56" lower="${j5_lo}" upper="${j5_hi}" velocity="${j5_vel}"/>
    <axis xyz="0 1 0"/>
    <origin rpy="0 0 0" xyz="0 0 0"/>
  </joint>

  <link name="${nameofManipulator}_link5">
    <visual>
      <geometry>
        <mesh filename="package://rokae_description/meshes/${nameofManipulator}/visual/${nameofManipulator}_link5.stl" scale="0.001 0.001 0.001"/>
      </geometry>
      <origin rpy="0 0 0" xyz="0 0 0"/>
      <material name="white"/>
    </visual>
    <inertial>
      <mass value="1.289"/>
      <inertia ixx="0.01" ixy="0" ixz="0" iyy="0.01" iyz="0" izz="0.01"/>
      <origin rpy="0 0 0" xyz="0.017 0.001 0"/>
    </inertial>
    <collision>
      <geometry>
        <mesh filename="package://rokae_description/meshes/${nameofManipulator}/collision/${nameofManipulator}_link5.stl" scale="0.001 0.001 0.001"/>
      </geometry>
      <origin rpy="0 0 0" xyz="0 0 0"/>
    </collision>
  </link>

  <!-- param.json: joint6 [73, 0, 0] mm, axis X -->
  <joint name="joint6" type="revolute">
    <parent link="${nameofManipulator}_link5"/>
    <child link="${nameofManipulator}_link6"/>
    <limit effort="1.11" lower="${j6_lo}" upper="${j6_hi}" velocity="${j6_vel}"/>
    <axis xyz="1 0 0"/>
    <origin rpy="0 0 0" xyz="0.073 0 0"/>
  </joint>

  <link name="${nameofManipulator}_link6">
    <visual>
      <geometry>
        <mesh filename="package://rokae_description/meshes/${nameofManipulator}/visual/${nameofManipulator}_link6.stl" scale="0.001 0.001 0.001"/>
      </geometry>
      <origin rpy="0 0 0" xyz="0 0 0"/>
      <material name="white"/>
    </visual>
    <inertial>
      <mass value="0.210"/>
      <inertia ixx="0.002" ixy="0" ixz="0" iyy="0.002" iyz="0" izz="0.002"/>
      <origin rpy="0 0 0" xyz="-0.011 0 0"/>
    </inertial>
    <collision>
      <geometry>
        <mesh filename="package://rokae_description/meshes/${nameofManipulator}/collision/${nameofManipulator}_link6.stl" scale="0.001 0.001 0.001"/>
      </geometry>
      <origin rpy="0 0 0" xyz="0 0 0"/>
    </collision>
  </link>

</robot>
